Workbook

Sheet Folha1
S2: Shopping 09/06/2026 | V2: PROMO 09/06/2026
A3: Nomenclatura Amont | B3: Nomenclatura Aval | C3: Grp | D3: GRUPO | E3: FIL | F3: FAM | G3: SFA | H3: ITM8 | I3: DESCRIÇÃO ARTIGO | J3: MARCA | K3: EAN | L3: TIPO | M3: PSYCHO | N3: PROMO PERM (LEADER) | O3: EDLP | P3: Argus | Q3: ST | R3: PVP Cadencier | S3: CONTINENTE | T3: LIDL | U3: PINGO-DOCE | V3: CNT | W3: LIDL | X3: PD | Y3: condição PVP | Z3: _DESVIO % | AA3: _DESVIO € | AB3: check | AC3: Campanha promo futura | AD3: PVP campanha | AE3: NOVO PVP | AF3: Comentarios (face ao suivi) | AG3: HISTORICO | AH3: feedback comercial
A4: g27b053 | B4: r40f34s02 | C4: =MID(A4,2,2) -> 27 | D4: =_xlfn.XLOOKUP(C4,Folha2!A:A,Folha2!B:B) -> TAKE AWAY | E4: =MID(A4,5,3) -> 053 | F4: =MID(B4,5,2) -> 34 | G4: =MID(B4,8,2) -> 02 | H4: 02032022 | I4: GYOZA DE FRANGO 144G | J4: TA TUNG | K4: 8436558315518 | L4: E | M4: N | N4: N | O4: N | P4: N | Q4: 01 | R4: 3.99 | S4: 3.99 | U4: 3.99 | Y4: =IF(OR(N4="O",O4="O"),IF(COUNT(V4:X4)>0,MIN(V4:X4),MIN(S4:U4)),IF(M4="O",MIN(S4:U4),IF(L4="E",IFERROR(MODE(S4:U4),MIN(S4:U4)),AVERAGE(S4:U4)))) -> 3.99 | Z4: =R4/Y4-1 -> 0 | AA4: =R4-Y4 -> 0 | AB4: =R4=Y4 -> TRUE
A5: g27b053 | B5: r40f34s04 | C5: =MID(A5,2,2) -> 27 | D5: =_xlfn.XLOOKUP(C5,Folha2!A:A,Folha2!B:B) -> TAKE AWAY | E5: =MID(A5,5,3) -> 053 | F5: =MID(B5,5,2) -> 34 | G5: =MID(B5,8,2) -> 04 | H5: 02175771 | I5: CHICKENBURGUER 2X135G | J5: M.RANOU | K5: 5604260343614 | L5: MP | M5: O | N5: N | O5: N | P5: O | Q5: 01 | R5: 2.69 | S5: 2.8 | Y5: =IF(OR(N5="O",O5="O"),IF(COUNT(V5:X5)>0,MIN(V5:X5),MIN(S5:U5)),IF(M5="O",MIN(S5:U5),IF(L5="E",IFERROR(MODE(S5:U5),MIN(S5:U5)),AVERAGE(S5:U5)))) -> 2.8 | Z5: =R5/Y5-1 -> -0.039285714 | AA5: =R5-Y5 -> -0.11 | AB5: =R5=Y5 -> FALSE | AC5: 11-06-2026 | AD5: 2.69
A6: g27b053 | B6: r40f34s04 | C6: =MID(A6,2,2) -> 27 | D6: =_xlfn.XLOOKUP(C6,Folha2!A:A,Folha2!B:B) -> TAKE AWAY | E6: =MID(A6,5,3) -> 053 | F6: =MID(B6,5,2) -> 34 | G6: =MID(B6,8,2) -> 04 | H6: 02175782 | I6: CHEESEBURGUER 2X150G | J6: M.RANOU | K6: 5604260343621 | L6: MP | M6: O | N6: N | O6: N | P6: O | Q6: 01 | R6: 2.75 | S6: 2.99 | T6: 2.62 | U6: 2.99 | Y6: =IF(OR(N6="O",O6="O"),IF(COUNT(V6:X6)>0,MIN(V6:X6),MIN(S6:U6)),IF(M6="O",MIN(S6:U6),IF(L6="E",IFERROR(MODE(S6:U6),MIN(S6:U6)),AVERAGE(S6:U6)))) -> 2.62 | Z6: =R6/Y6-1 -> 0.049618321 | AA6: =R6-Y6 -> 0.13 | AB6: =R6=Y6 -> FALSE | AC6: 11-06-2026 | AD6: 2.75
A7: g27b053 | B7: r40f34s04 | C7: =MID(A7,2,2) -> 27 | D7: =_xlfn.XLOOKUP(C7,Folha2!A:A,Folha2!B:B) -> TAKE AWAY | E7: =MID(A7,5,3) -> 053 | F7: =MID(B7,5,2) -> 34 | G7: =MID(B7,8,2) -> 04 | H7: 01942601 | I7: SANDES DELICIAS DO MAR 143G | J7: PORSI | K7: 5604260325788 | L7: MP | M7: N | N7: N | O7: N | P7: N | Q7: 01 | R7: 1.69 | S7: 1.5 | Y7: =IF(OR(N7="O",O7="O"),IF(COUNT(V7:X7)>0,MIN(V7:X7),MIN(S7:U7)),IF(M7="O",MIN(S7:U7),IF(L7="E",IFERROR(MODE(S7:U7),MIN(S7:U7)),AVERAGE(S7:U7)))) -> 1.5 | Z7: =R7/Y7-1 -> 0.12666667 | AA7: =R7-Y7 -> 0.19 | AB7: =R7=Y7 -> FALSE | AC7: 11-06-2026 | AD7: 1.69
A8: g27b053 | B8: r40f34s04 | C8: =MID(A8,2,2) -> 27 | D8: =_xlfn.XLOOKUP(C8,Folha2!A:A,Folha2!B:B) -> TAKE AWAY | E8: =MID(A8,5,3) -> 053 | F8: =MID(B8,5,2) -> 34 | G8: =MID(B8,8,2) -> 04 | H8: 01942623 | I8: SANDES MISTA 200G | J8: PORSI | K8: 5604260325771 | L8: MP | M8: N | N8: N | O8: N | P8: N | Q8: 01 | R8: 1.89 | S8: 1.89 | Y8: =IF(OR(N8="O",O8="O"),IF(COUNT(V8:X8)>0,MIN(V8:X8),MIN(S8:U8)),IF(M8="O",MIN(S8:U8),IF(L8="E",IFERROR(MODE(S8:U8),MIN(S8:U8)),AVERAGE(S8:U8)))) -> 1.89 | Z8: =R8/Y8-1 -> 0 | AA8: =R8-Y8 -> 0 | AB8: =R8=Y8 -> TRUE | AC8: 11-06-2026 | AD8: 1.89
A9: g27b053 | B9: r40f34s04 | C9: =MID(A9,2,2) -> 27 | D9: =_xlfn.XLOOKUP(C9,Folha2!A:A,Folha2!B:B) -> TAKE AWAY | E9: =MID(A9,5,3) -> 053 | F9: =MID(B9,5,2) -> 34 | G9: =MID(B9,8,2) -> 04 | H9: 01942612 | I9: SANDES FRANGO 174G | J9: PORSI | K9: 5604260325795 | L9: MP | M9: N | N9: N | O9: N | P9: N | Q9: 01 | R9: 1.99 | S9: 1.88 | Y9: =IF(OR(N9="O",O9="O"),IF(COUNT(V9:X9)>0,MIN(V9:X9),MIN(S9:U9)),IF(M9="O",MIN(S9:U9),IF(L9="E",IFERROR(MODE(S9:U9),MIN(S9:U9)),AVERAGE(S9:U9)))) -> 1.88 | Z9: =R9/Y9-1 -> 0.058510638 | AA9: =R9-Y9 -> 0.11 | AB9: =R9=Y9 -> FALSE | AC9: 11-06-2026 | AD9: 1.99
A10: g27b053 | B10: r40f34s04 | C10: =MID(A10,2,2) -> 27 | D10: =_xlfn.XLOOKUP(C10,Folha2!A:A,Folha2!B:B) -> TAKE AWAY | E10: =MID(A10,5,3) -> 053 | F10: =MID(B10,5,2) -> 34 | G10: =MID(B10,8,2) -> 04 | H10: 01983452 | I10: ROSCA PRES.SERRANO/QUEIJO 420G | J10: PORSI | K10: 5604260328734 | L10: MP | M10: N | N10: N | O10: N | P10: N | Q10: 01 | R10: 3.49 | S10: 3.49 | Y10: =IF(OR(N10="O",O10="O"),IF(COUNT(V10:X10)>0,MIN(V10:X10),MIN(S10:U10)),IF(M10="O",MIN(S10:U10),IF(L10="E",IFERROR(MODE(S10:U10),MIN(S10:U10)),AVERAGE(S10:U10)))) -> 3.49 | Z10: =R10/Y10-1 -> 0 | AA10: =R10-Y10 -> 0 | AB10: =R10=Y10 -> TRUE | AC10: 25-06-2026 | AD10: 3.49
A11: g27b053 | B11: r40f34s06 | C11: =MID(A11,2,2) -> 27 | D11: =_xlfn.XLOOKUP(C11,Folha2!A:A,Folha2!B:B) -> TAKE AWAY | E11: =MID(A11,5,3) -> 053 | F11: =MID(B11,5,2) -> 34 | G11: =MID(B11,8,2) -> 06 | H11: 02175793 | I11: PIZZA FIAMBRE & QUEIJO 360G | J11: CAMPOFRIO | K11: 8410320033503 | L11: E | M11: N | N11: N | O11: N | P11: N | Q11: 01 | R11: 3.99 | S11: 3.99 | Y11: =IF(OR(N11="O",O11="O"),IF(COUNT(V11:X11)>0,MIN(V11:X11),MIN(S11:U11)),IF(M11="O",MIN(S11:U11),IF(L11="E",IFERROR(MODE(S11:U11),MIN(S11:U11)),AVERAGE(S11:U11)))) -> 3.99 | Z11: =R11/Y11-1 -> 0 | AA11: =R11-Y11 -> 0 | AB11: =R11=Y11 -> TRUE | AC11: 04-06-2026 | AD11: 2.99
A12: g27b053 | B12: r40f34s06 | C12: =MID(A12,2,2) -> 27 | D12: =_xlfn.XLOOKUP(C12,Folha2!A:A,Folha2!B:B) -> TAKE AWAY | E12: =MID(A12,5,3) -> 053 | F12: =MID(B12,5,2) -> 34 | G12: =MID(B12,8,2) -> 06 | H12: 02175802 | I12: PIZZA BARBECUE 410G | J12: CAMPOFRIO | K12: 8410320034319 | L12: E | M12: N | N12: N | O12: N | P12: N | Q12: 01 | R12: 3.99 | S12: 3.99 | Y12: =IF(OR(N12="O",O12="O"),IF(COUNT(V12:X12)>0,MIN(V12:X12),MIN(S12:U12)),IF(M12="O",MIN(S12:U12),IF(L12="E",IFERROR(MODE(S12:U12),MIN(S12:U12)),AVERAGE(S12:U12)))) -> 3.99 | Z12: =R12/Y12-1 -> 0 | AA12: =R12-Y12 -> 0 | AB12: =R12=Y12 -> TRUE | AC12: 04-06-2026 | AD12: 2.99
A13: g27b053 | B13: r40f34s06 | C13: =MID(A13,2,2) -> 27 | D13: =_xlfn.XLOOKUP(C13,Folha2!A:A,Folha2!B:B) -> TAKE AWAY | E13: =MID(A13,5,3) -> 053 | F13: =MID(B13,5,2) -> 34 | G13: =MID(B13,8,2) -> 06 | H13: 02175813 | I13: PIZZA CARBONARA 360G | J13: CAMPOFRIO | K13: 8410320133692 | L13: E | M13: N | N13: N | O13: N | P13: N | Q13: 01 | R13: 3.99 | S13: 3.99 | Y13: =IF(OR(N13="O",O13="O"),IF(COUNT(V13:X13)>0,MIN(V13:X13),MIN(S13:U13)),IF(M13="O",MIN(S13:U13),IF(L13="E",IFERROR(MODE(S13:U13),MIN(S13:U13)),AVERAGE(S13:U13)))) -> 3.99 | Z13: =R13/Y13-1 -> 0 | AA13: =R13-Y13 -> 0 | AB13: =R13=Y13 -> TRUE | AC13: 04-06-2026 | AD13: 2.99
A14: g27b053 | B14: r40f34s06 | C14: =MID(A14,2,2) -> 27 | D14: =_xlfn.XLOOKUP(C14,Folha2!A:A,Folha2!B:B) -> TAKE AWAY | E14: =MID(A14,5,3) -> 053 | F14: =MID(B14,5,2) -> 34 | G14: =MID(B14,8,2) -> 06 | H14: 02038800 | I14: PIZZA ROMANA 410G | J14: PORSI | K14: 5604260331437 | L14: MP | M14: O | N14: N | O14: N | P14: O | Q14: 01 | R14: 2.69 | S14: 2.66 | T14: 2.56 | U14: 2.66 | Y14: =IF(OR(N14="O",O14="O"),IF(COUNT(V14:X14)>0,MIN(V14:X14),MIN(S14:U14)),IF(M14="O",MIN(S14:U14),IF(L14="E",IFERROR(MODE(S14:U14),MIN(S14:U14)),AVERAGE(S14:U14)))) -> 2.56 | Z14: =R14/Y14-1 -> 0.05078125 | AA14: =R14-Y14 -> 0.13 | AB14: =R14=Y14 -> FALSE | AC14: 11-06-2026 | AD14: 2.69
A15: g27b053 | B15: r40f34s06 | C15: =MID(A15,2,2) -> 27 | D15: =_xlfn.XLOOKUP(C15,Folha2!A:A,Folha2!B:B) -> TAKE AWAY | E15: =MID(A15,5,3) -> 053 | F15: =MID(B15,5,2) -> 34 | G15: =MID(B15,8,2) -> 06 | H15: 02038791 | I15: PIZZA FIAMBRE E QUEIJO 410G | J15: PORSI | K15: 5604260331420 | L15: MP | M15: O | N15: N | O15: N | P15: O | Q15: 01 | R15: 2.69 | S15: 2.69 | T15: 2.66 | U15: 2.69 | Y15: =IF(OR(N15="O",O15="O"),IF(COUNT(V15:X15)>0,MIN(V15:X15),MIN(S15:U15)),IF(M15="O",MIN(S15:U15),IF(L15="E",IFERROR(MODE(S15:U15),MIN(S15:U15)),AVERAGE(S15:U15)))) -> 2.66 | Z15: =R15/Y15-1 -> 0.011278195 | AA15: =R15-Y15 -> 0.03 | AB15: =R15=Y15 -> FALSE | AC15: 11-06-2026 | AD15: 2.69
A16: g27b053 | B16: r40f34s06 | C16: =MID(A16,2,2) -> 27 | D16: =_xlfn.XLOOKUP(C16,Folha2!A:A,Folha2!B:B) -> TAKE AWAY | E16: =MID(A16,5,3) -> 053 | F16: =MID(B16,5,2) -> 34 | G16: =MID(B16,8,2) -> 06 | H16: 02038776 | I16: PIZZA 4 QUEIJOS 380G | J16: PORSI | K16: 5604260331406 | L16: MP | M16: O | N16: N | O16: N | P16: O | Q16: 01 | R16: 2.75 | S16: 2.75 | T16: 2.68 | U16: 2.82 | Y16: =IF(OR(N16="O",O16="O"),IF(COUNT(V16:X16)>0,MIN(V16:X16),MIN(S16:U16)),IF(M16="O",MIN(S16:U16),IF(L16="E",IFERROR(MODE(S16:U16),MIN(S16:U16)),AVERAGE(S16:U16)))) -> 2.68 | Z16: =R16/Y16-1 -> 0.026119403 | AA16: =R16-Y16 -> 0.07 | AB16: =R16=Y16 -> FALSE | AC16: 11-06-2026 | AD16: 2.75
A17: g27b053 | B17: r40f34s06 | C17: =MID(A17,2,2) -> 27 | D17: =_xlfn.XLOOKUP(C17,Folha2!A:A,Folha2!B:B) -> TAKE AWAY | E17: =MID(A17,5,3) -> 053 | F17: =MID(B17,5,2) -> 34 | G17: =MID(B17,8,2) -> 06 | H17: 02038765 | I17: PIZZA CARBONARA 415G | J17: PORSI | K17: 5604260331390 | L17: MP | M17: O | N17: N | O17: N | P17: O | Q17: 01 | R17: 2.89 | S17: 2.93 | T17: 2.79 | U17: 2.89 | Y17: =IF(OR(N17="O",O17="O"),IF(COUNT(V17:X17)>0,MIN(V17:X17),MIN(S17:U17)),IF(M17="O",MIN(S17:U17),IF(L17="E",IFERROR(MODE(S17:U17),MIN(S17:U17)),AVERAGE(S17:U17)))) -> 2.79 | Z17: =R17/Y17-1 -> 0.035842294 | AA17: =R17-Y17 -> 0.1 | AB17: =R17=Y17 -> FALSE | AC17: 11-06-2026 | AD17: 2.89
A18: g27b053 | B18: r40f34s06 | C18: =MID(A18,2,2) -> 27 | D18: =_xlfn.XLOOKUP(C18,Folha2!A:A,Folha2!B:B) -> TAKE AWAY | E18: =MID(A18,5,3) -> 053 | F18: =MID(B18,5,2) -> 34 | G18: =MID(B18,8,2) -> 06 | H18: 02038780 | I18: PIZZA ATUM E BACON 410G | J18: PORSI | K18: 5604260331413 | L18: MP | M18: O | N18: N | O18: N | P18: O | Q18: 01 | R18: 2.95 | S18: 2.96 | T18: 2.86 | U18: 2.93 | Y18: =IF(OR(N18="O",O18="O"),IF(COUNT(V18:X18)>0,MIN(V18:X18),MIN(S18:U18)),IF(M18="O",MIN(S18:U18),IF(L18="E",IFERROR(MODE(S18:U18),MIN(S18:U18)),AVERAGE(S18:U18)))) -> 2.86 | Z18: =R18/Y18-1 -> 0.031468531 | AA18: =R18-Y18 -> 0.09 | AB18: =R18=Y18 -> FALSE | AC18: 11-06-2026 | AD18: 2.95
A19: g27b053 | B19: r40f34s06 | C19: =MID(A19,2,2) -> 27 | D19: =_xlfn.XLOOKUP(C19,Folha2!A:A,Folha2!B:B) -> TAKE AWAY | E19: =MID(A19,5,3) -> 053 | F19: =MID(B19,5,2) -> 34 | G19: =MID(B19,8,2) -> 06 | H19: 02038811 | I19: PIZZA BARBECUE 410G | J19: PORSI | K19: 5604260331444 | L19: MP | M19: O | N19: N | O19: N | P19: O | Q19: 01 | R19: 2.99 | S19: 2.96 | T19: 2.86 | Y19: =IF(OR(N19="O",O19="O"),IF(COUNT(V19:X19)>0,MIN(V19:X19),MIN(S19:U19)),IF(M19="O",MIN(S19:U19),IF(L19="E",IFERROR(MODE(S19:U19),MIN(S19:U19)),AVERAGE(S19:U19)))) -> 2.86 | Z19: =R19/Y19-1 -> 0.045454545 | AA19: =R19-Y19 -> 0.13 | AB19: =R19=Y19 -> FALSE | AC19: 11-06-2026 | AD19: 2.99
A20: g27b053 | B20: r40f34s10 | C20: =MID(A20,2,2) -> 27 | D20: =_xlfn.XLOOKUP(C20,Folha2!A:A,Folha2!B:B) -> TAKE AWAY | E20: =MID(A20,5,3) -> 053 | F20: =MID(B20,5,2) -> 34 | G20: =MID(B20,8,2) -> 10 | H20: 01647535 | I20: GASPACHO ORIGINAL 1L | J20: ALVALLE | K20: 8422174010029 | L20: E | M20: N | N20: N | O20: N | P20: N | Q20: 01 | R20: 4.49 | S20: 4.49 | V20: 2.24 | Y20: =IF(OR(N20="O",O20="O"),IF(COUNT(V20:X20)>0,MIN(V20:X20),MIN(S20:U20)),IF(M20="O",MIN(S20:U20),IF(L20="E",IFERROR(MODE(S20:U20),MIN(S20:U20)),AVERAGE(S20:U20)))) -> 4.49 | Z20: =R20/Y20-1 -> 0 | AA20: =R20-Y20 -> 0 | AB20: =R20=Y20 -> TRUE | AC20: 09-07-2026 | AD20: 2.89
A21: g27b053 | B21: r40f34s10 | C21: =MID(A21,2,2) -> 27 | D21: =_xlfn.XLOOKUP(C21,Folha2!A:A,Folha2!B:B) -> TAKE AWAY | E21: =MID(A21,5,3) -> 053 | F21: =MID(B21,5,2) -> 34 | G21: =MID(B21,8,2) -> 10 | H21: 01754795 | I21: CREME DE CENOURA 400G | J21: PORSI | K21: 5604260298181 | L21: MP | M21: N | N21: N | O21: N | P21: N | Q21: 01 | R21: 1.39 | S21: 1.59 | T21: 1.39 | U21: 1.59 | Y21: =IF(OR(N21="O",O21="O"),IF(COUNT(V21:X21)>0,MIN(V21:X21),MIN(S21:U21)),IF(M21="O",MIN(S21:U21),IF(L21="E",IFERROR(MODE(S21:U21),MIN(S21:U21)),AVERAGE(S21:U21)))) -> 1.5233333 | Z21: =R21/Y21-1 -> -0.087527352 | AA21: =R21-Y21 -> -0.13333333 | AB21: =R21=Y21 -> FALSE | AC21: 02-07-2026 | AD21: 1.39
A22: g27b053 | B22: r40f34s10 | C22: =MID(A22,2,2) -> 27 | D22: =_xlfn.XLOOKUP(C22,Folha2!A:A,Folha2!B:B) -> TAKE AWAY | E22: =MID(A22,5,3) -> 053 | F22: =MID(B22,5,2) -> 34 | G22: =MID(B22,8,2) -> 10 | H22: 01754784 | I22: SOPA LEGUMES 400G | J22: PORSI | K22: 5604260298174 | L22: MP | M22: N | N22: N | O22: N | P22: N | Q22: 01 | R22: 1.39 | S22: 1.79 | T22: 1.39 | Y22: =IF(OR(N22="O",O22="O"),IF(COUNT(V22:X22)>0,MIN(V22:X22),MIN(S22:U22)),IF(M22="O",MIN(S22:U22),IF(L22="E",IFERROR(MODE(S22:U22),MIN(S22:U22)),AVERAGE(S22:U22)))) -> 1.59 | Z22: =R22/Y22-1 -> -0.12578616 | AA22: =R22-Y22 -> -0.2 | AB22: =R22=Y22 -> FALSE | AC22: 11-06-2026 | AD22: 1.39
A23: g27b053 | B23: r40f34s10 | C23: =MID(A23,2,2) -> 27 | D23: =_xlfn.XLOOKUP(C23,Folha2!A:A,Folha2!B:B) -> TAKE AWAY | E23: =MID(A23,5,3) -> 053 | F23: =MID(B23,5,2) -> 34 | G23: =MID(B23,8,2) -> 10 | H23: 02106296 | I23: CALDO VERDE C/CHOURICO 400G | J23: PORSI | K23: 5604260332021 | L23: MP | M23: N | N23: N | O23: N | P23: N | Q23: 01 | R23: 1.69 | S23: 1.59 | Y23: =IF(OR(N23="O",O23="O"),IF(COUNT(V23:X23)>0,MIN(V23:X23),MIN(S23:U23)),IF(M23="O",MIN(S23:U23),IF(L23="E",IFERROR(MODE(S23:U23),MIN(S23:U23)),AVERAGE(S23:U23)))) -> 1.59 | Z23: =R23/Y23-1 -> 0.062893082 | AA23: =R23-Y23 -> 0.1 | AB23: =R23=Y23 -> FALSE
A24: g27b053 | B24: r40f34s10 | C24: =MID(A24,2,2) -> 27 | D24: =_xlfn.XLOOKUP(C24,Folha2!A:A,Folha2!B:B) -> TAKE AWAY | E24: =MID(A24,5,3) -> 053 | F24: =MID(B24,5,2) -> 34 | G24: =MID(B24,8,2) -> 10 | H24: 01851894 | I24: SOPA DE AGRIAO 400G | J24: PORSI | K24: 5604260310098 | L24: MP | M24: N | N24: N | O24: N | P24: N | Q24: 01 | R24: 1.89 | S24: 1.69 | Y24: =IF(OR(N24="O",O24="O"),IF(COUNT(V24:X24)>0,MIN(V24:X24),MIN(S24:U24)),IF(M24="O",MIN(S24:U24),IF(L24="E",IFERROR(MODE(S24:U24),MIN(S24:U24)),AVERAGE(S24:U24)))) -> 1.69 | Z24: =R24/Y24-1 -> 0.1183432 | AA24: =R24-Y24 -> 0.2 | AB24: =R24=Y24 -> FALSE | AC24: 11-06-2026 | AD24: 1.89
A25: g27b053 | B25: r40f34s10 | C25: =MID(A25,2,2) -> 27 | D25: =_xlfn.XLOOKUP(C25,Folha2!A:A,Folha2!B:B) -> TAKE AWAY | E25: =MID(A25,5,3) -> 053 | F25: =MID(B25,5,2) -> 34 | G25: =MID(B25,8,2) -> 10 | H25: 01981345 | I25: SOPA DE FEIJAO VERDE 400G | J25: PORSI | K25: 5604260328536 | L25: MP | M25: N | N25: N | O25: N | P25: N | Q25: 01 | R25: 1.89 | S25: 1.79 | Y25: =IF(OR(N25="O",O25="O"),IF(COUNT(V25:X25)>0,MIN(V25:X25),MIN(S25:U25)),IF(M25="O",MIN(S25:U25),IF(L25="E",IFERROR(MODE(S25:U25),MIN(S25:U25)),AVERAGE(S25:U25)))) -> 1.79 | Z25: =R25/Y25-1 -> 0.055865922 | AA25: =R25-Y25 -> 0.1 | AB25: =R25=Y25 -> FALSE | AC25: 11-06-2026 | AD25: 1.89
A26: g27b053 | B26: r40f34s10 | C26: =MID(A26,2,2) -> 27 | D26: =_xlfn.XLOOKUP(C26,Folha2!A:A,Folha2!B:B) -> TAKE AWAY | E26: =MID(A26,5,3) -> 053 | F26: =MID(B26,5,2) -> 34 | G26: =MID(B26,8,2) -> 10 | H26: 02106305 | I26: SOPA CAMPONESA 400G | J26: PORSI | K26: 5604260335428 | L26: MP | M26: N | N26: N | O26: N | P26: N | Q26: 01 | R26: 1.89 | S26: 1.79 | Y26: =IF(OR(N26="O",O26="O"),IF(COUNT(V26:X26)>0,MIN(V26:X26),MIN(S26:U26)),IF(M26="O",MIN(S26:U26),IF(L26="E",IFERROR(MODE(S26:U26),MIN(S26:U26)),AVERAGE(S26:U26)))) -> 1.79 | Z26: =R26/Y26-1 -> 0.055865922 | AA26: =R26-Y26 -> 0.1 | AB26: =R26=Y26 -> FALSE | AC26: 11-06-2026 | AD26: 1.89
A27: g27b053 | B27: r40f34s10 | C27: =MID(A27,2,2) -> 27 | D27: =_xlfn.XLOOKUP(C27,Folha2!A:A,Folha2!B:B) -> TAKE AWAY | E27: =MID(A27,5,3) -> 053 | F27: =MID(B27,5,2) -> 34 | G27: =MID(B27,8,2) -> 10 | H27: 01794261 | I27: GASPACHO 1L | J27: PORSI | K27: 5604260301478 | L27: MP | M27: N | N27: N | O27: N | P27: N | Q27: 01 | R27: 2.09 | S27: 1.89 | U27: 1.89 | Y27: =IF(OR(N27="O",O27="O"),IF(COUNT(V27:X27)>0,MIN(V27:X27),MIN(S27:U27)),IF(M27="O",MIN(S27:U27),IF(L27="E",IFERROR(MODE(S27:U27),MIN(S27:U27)),AVERAGE(S27:U27)))) -> 1.89 | Z27: =R27/Y27-1 -> 0.10582011 | AA27: =R27-Y27 -> 0.2 | AB27: =R27=Y27 -> FALSE
A28: g27b053 | B28: r40f34s10 | C28: =MID(A28,2,2) -> 27 | D28: =_xlfn.XLOOKUP(C28,Folha2!A:A,Folha2!B:B) -> TAKE AWAY | E28: =MID(A28,5,3) -> 053 | F28: =MID(B28,5,2) -> 34 | G28: =MID(B28,8,2) -> 10 | H28: 01932962 | I28: SOPA DE LEGUMES 800G | J28: PORSI | K28: 5604260320561 | L28: MP | M28: O | N28: N | O28: N | P28: O | Q28: 01 | R28: 2.49 | S28: 2.49 | U28: 2.48 | Y28: =IF(OR(N28="O",O28="O"),IF(COUNT(V28:X28)>0,MIN(V28:X28),MIN(S28:U28)),IF(M28="O",MIN(S28:U28),IF(L28="E",IFERROR(MODE(S28:U28),MIN(S28:U28)),AVERAGE(S28:U28)))) -> 2.48 | Z28: =R28/Y28-1 -> 0.0040322581 | AA28: =R28-Y28 -> 0.01 | AB28: =R28=Y28 -> FALSE | AC28: 04-06-2026 | AD28: 1.99
A29: g27b053 | B29: r40f34s10 | C29: =MID(A29,2,2) -> 27 | D29: =_xlfn.XLOOKUP(C29,Folha2!A:A,Folha2!B:B) -> TAKE AWAY | E29: =MID(A29,5,3) -> 053 | F29: =MID(B29,5,2) -> 34 | G29: =MID(B29,8,2) -> 10 | H29: 01932951 | I29: CREME DE CENOURA 800G | J29: PORSI | K29: 5604260320578 | L29: MP | M29: O | N29: N | O29: N | P29: O | Q29: 01 | R29: 2.69 | S29: 2.49 | Y29: =IF(OR(N29="O",O29="O"),IF(COUNT(V29:X29)>0,MIN(V29:X29),MIN(S29:U29)),IF(M29="O",MIN(S29:U29),IF(L29="E",IFERROR(MODE(S29:U29),MIN(S29:U29)),AVERAGE(S29:U29)))) -> 2.49 | Z29: =R29/Y29-1 -> 0.080321285 | AA29: =R29-Y29 -> 0.2 | AB29: =R29=Y29 -> FALSE | AC29: 04-06-2026 | AD29: 1.99
A30: g27b053 | B30: r40f34s10 | C30: =MID(A30,2,2) -> 27 | D30: =_xlfn.XLOOKUP(C30,Folha2!A:A,Folha2!B:B) -> TAKE AWAY | E30: =MID(A30,5,3) -> 053 | F30: =MID(B30,5,2) -> 34 | G30: =MID(B30,8,2) -> 10 | H30: 01932973 | I30: SOPA DE AGRIAO 800G | J30: PORSI | K30: 5604260323197 | L30: MP | M30: O | N30: N | O30: N | P30: O | Q30: 01 | R30: 2.69 | S30: 2.49 | Y30: =IF(OR(N30="O",O30="O"),IF(COUNT(V30:X30)>0,MIN(V30:X30),MIN(S30:U30)),IF(M30="O",MIN(S30:U30),IF(L30="E",IFERROR(MODE(S30:U30),MIN(S30:U30)),AVERAGE(S30:U30)))) -> 2.49 | Z30: =R30/Y30-1 -> 0.080321285 | AA30: =R30-Y30 -> 0.2 | AB30: =R30=Y30 -> FALSE | AC30: 04-06-2026 | AD30: 1.99
A31: g27b053 | B31: r40f34s12 | C31: =MID(A31,2,2) -> 27 | D31: =_xlfn.XLOOKUP(C31,Folha2!A:A,Folha2!B:B) -> TAKE AWAY | E31: =MID(A31,5,3) -> 053 | F31: =MID(B31,5,2) -> 34 | G31: =MID(B31,8,2) -> 12 | H31: 01856021 | I31: MASSA CARBONARA 300G | J31: PORSI | K31: 5604260309917 | L31: MP | M31: N | N31: N | O31: N | P31: N | Q31: 01 | R31: 2.99 | S31: 2.99 | T31: 2.36 | Y31: =IF(OR(N31="O",O31="O"),IF(COUNT(V31:X31)>0,MIN(V31:X31),MIN(S31:U31)),IF(M31="O",MIN(S31:U31),IF(L31="E",IFERROR(MODE(S31:U31),MIN(S31:U31)),AVERAGE(S31:U31)))) -> 2.675 | Z31: =R31/Y31-1 -> 0.11775701 | AA31: =R31-Y31 -> 0.315 | AB31: =R31=Y31 -> FALSE
A32: g27b053 | B32: r40f34s12 | C32: =MID(A32,2,2) -> 27 | D32: =_xlfn.XLOOKUP(C32,Folha2!A:A,Folha2!B:B) -> TAKE AWAY | E32: =MID(A32,5,3) -> 053 | F32: =MID(B32,5,2) -> 34 | G32: =MID(B32,8,2) -> 12 | H32: 01826725 | I32: ARROZ DE PATO 250G | J32: PORSI | K32: 5604260304066 | L32: MP | M32: N | N32: N | O32: N | P32: N | Q32: 01 | R32: 2.99 | S32: 3.32 | T32: 2.99 | Y32: =IF(OR(N32="O",O32="O"),IF(COUNT(V32:X32)>0,MIN(V32:X32),MIN(S32:U32)),IF(M32="O",MIN(S32:U32),IF(L32="E",IFERROR(MODE(S32:U32),MIN(S32:U32)),AVERAGE(S32:U32)))) -> 3.155 | Z32: =R32/Y32-1 -> -0.05229794 | AA32: =R32-Y32 -> -0.165 | AB32: =R32=Y32 -> FALSE | AC32: 18-06-2026 | AD32: 2.99
A33: g27b053 | B33: r40f34s12 | C33: =MID(A33,2,2) -> 27 | D33: =_xlfn.XLOOKUP(C33,Folha2!A:A,Folha2!B:B) -> TAKE AWAY | E33: =MID(A33,5,3) -> 053 | F33: =MID(B33,5,2) -> 34 | G33: =MID(B33,8,2) -> 12 | H33: 01973960 | I33: CHILLI COM CARNE E ARROZ 350G | J33: PORSI | K33: 5604260328352 | L33: MP | M33: N | N33: N | O33: N | P33: N | Q33: 01 | R33: 3.59 | S33: 3.59 | Y33: =IF(OR(N33="O",O33="O"),IF(COUNT(V33:X33)>0,MIN(V33:X33),MIN(S33:U33)),IF(M33="O",MIN(S33:U33),IF(L33="E",IFERROR(MODE(S33:U33),MIN(S33:U33)),AVERAGE(S33:U33)))) -> 3.59 | Z33: =R33/Y33-1 -> 0 | AA33: =R33-Y33 -> 0 | AB33: =R33=Y33 -> TRUE | AC33: 09-07-2026 | AD33: 3.59
A34: g27b053 | B34: r40f34s12 | C34: =MID(A34,2,2) -> 27 | D34: =_xlfn.XLOOKUP(C34,Folha2!A:A,Folha2!B:B) -> TAKE AWAY | E34: =MID(A34,5,3) -> 053 | F34: =MID(B34,5,2) -> 34 | G34: =MID(B34,8,2) -> 12 | H34: 01826751 | I34: ESPARGUETE BOLONHESA 350G | J34: PORSI | K34: 5604260304097 | L34: MP | M34: N | N34: N | O34: N | P34: N | Q34: 01 | R34: 3.59 | S34: 3.99 | T34: 2.75 | Y34: =IF(OR(N34="O",O34="O"),IF(COUNT(V34:X34)>0,MIN(V34:X34),MIN(S34:U34)),IF(M34="O",MIN(S34:U34),IF(L34="E",IFERROR(MODE(S34:U34),MIN(S34:U34)),AVERAGE(S34:U34)))) -> 3.37 | Z34: =R34/Y34-1 -> 0.065281899 | AA34: =R34-Y34 -> 0.22 | AB34: =R34=Y34 -> FALSE | AC34: 09-07-2026 | AD34: 2.99
A35: g27b053 | B35: r40f34s12 | C35: =MID(A35,2,2) -> 27 | D35: =_xlfn.XLOOKUP(C35,Folha2!A:A,Folha2!B:B) -> TAKE AWAY | E35: =MID(A35,5,3) -> 053 | F35: =MID(B35,5,2) -> 34 | G35: =MID(B35,8,2) -> 12 | H35: 01973971 | I35: EMPADAO CARNE GRATINADO 350G | J35: PORSI | K35: 5604260327607 | L35: MP | M35: N | N35: N | O35: N | P35: N | Q35: 01 | R35: 3.99 | S35: 4.02 | Y35: =IF(OR(N35="O",O35="O"),IF(COUNT(V35:X35)>0,MIN(V35:X35),MIN(S35:U35)),IF(M35="O",MIN(S35:U35),IF(L35="E",IFERROR(MODE(S35:U35),MIN(S35:U35)),AVERAGE(S35:U35)))) -> 4.02 | Z35: =R35/Y35-1 -> -0.0074626866 | AA35: =R35-Y35 -> -0.03 | AB35: =R35=Y35 -> FALSE | AC35: 02-07-2026 | AD35: 3.99
A36: g27b053 | B36: r40f34s12 | C36: =MID(A36,2,2) -> 27 | D36: =_xlfn.XLOOKUP(C36,Folha2!A:A,Folha2!B:B) -> TAKE AWAY | E36: =MID(A36,5,3) -> 053 | F36: =MID(B36,5,2) -> 34 | G36: =MID(B36,8,2) -> 12 | H36: 01973982 | I36: CARIL DE FRANGO 350G | J36: PORSI | K36: 5604260328369 | L36: MP | M36: N | N36: N | O36: N | P36: N | Q36: 01 | R36: 4.69 | S36: 4.66 | Y36: =IF(OR(N36="O",O36="O"),IF(COUNT(V36:X36)>0,MIN(V36:X36),MIN(S36:U36)),IF(M36="O",MIN(S36:U36),IF(L36="E",IFERROR(MODE(S36:U36),MIN(S36:U36)),AVERAGE(S36:U36)))) -> 4.66 | Z36: =R36/Y36-1 -> 0.0064377682 | AA36: =R36-Y36 -> 0.03 | AB36: =R36=Y36 -> FALSE
A37: g27b053 | B37: r40f34s12 | C37: =MID(A37,2,2) -> 27 | D37: =_xlfn.XLOOKUP(C37,Folha2!A:A,Folha2!B:B) -> TAKE AWAY | E37: =MID(A37,5,3) -> 053 | F37: =MID(B37,5,2) -> 34 | G37: =MID(B37,8,2) -> 12 | H37: 01912133 | I37: FRANCESINHA 500G | J37: PORSI | K37: 5604260309900 | L37: MP | M37: N | N37: N | O37: N | P37: N | Q37: 01 | R37: 6.49 | S37: 6.49 | T37: 6.49 | Y37: =IF(OR(N37="O",O37="O"),IF(COUNT(V37:X37)>0,MIN(V37:X37),MIN(S37:U37)),IF(M37="O",MIN(S37:U37),IF(L37="E",IFERROR(MODE(S37:U37),MIN(S37:U37)),AVERAGE(S37:U37)))) -> 6.49 | Z37: =R37/Y37-1 -> 0 | AA37: =R37-Y37 -> 0 | AB37: =R37=Y37 -> TRUE | AC37: 09-07-2026 | AD37: 6.49
A38: g27b053 | B38: r40f34s12 | C38: =MID(A38,2,2) -> 27 | D38: =_xlfn.XLOOKUP(C38,Folha2!A:A,Folha2!B:B) -> TAKE AWAY | E38: =MID(A38,5,3) -> 053 | F38: =MID(B38,5,2) -> 34 | G38: =MID(B38,8,2) -> 12 | H38: 01813313 | I38: LASANHA A BOLONHESA 350G | J38: RANA | K38: 8001665127684 | L38: E | M38: N | N38: N | O38: N | P38: N | Q38: 01 | R38: 4.49 | S38: 4.49 | U38: 4.49 | Y38: =IF(OR(N38="O",O38="O"),IF(COUNT(V38:X38)>0,MIN(V38:X38),MIN(S38:U38)),IF(M38="O",MIN(S38:U38),IF(L38="E",IFERROR(MODE(S38:U38),MIN(S38:U38)),AVERAGE(S38:U38)))) -> 4.49 | Z38: =R38/Y38-1 -> 0 | AA38: =R38-Y38 -> 0 | AB38: =R38=Y38 -> TRUE | AC38: 23-07-2026 | AD38: 3.34
A39: g27b053 | B39: r40f34s12 | C39: =MID(A39,2,2) -> 27 | D39: =_xlfn.XLOOKUP(C39,Folha2!A:A,Folha2!B:B) -> TAKE AWAY | E39: =MID(A39,5,3) -> 053 | F39: =MID(B39,5,2) -> 34 | G39: =MID(B39,8,2) -> 12 | H39: 02032011 | I39: YAKISOBA COM FRANGO 250G | J39: TA TUNG | K39: 8436558315839 | L39: E | M39: N | N39: N | O39: N | P39: N | Q39: 01 | R39: 4.99 | U39: 4.99 | Y39: =IF(OR(N39="O",O39="O"),IF(COUNT(V39:X39)>0,MIN(V39:X39),MIN(S39:U39)),IF(M39="O",MIN(S39:U39),IF(L39="E",IFERROR(MODE(S39:U39),MIN(S39:U39)),AVERAGE(S39:U39)))) -> 4.99 | Z39: =R39/Y39-1 -> 0 | AA39: =R39-Y39 -> 0 | AB39: =R39=Y39 -> TRUE
A40: g27b053 | B40: r40f34s13 | C40: =MID(A40,2,2) -> 27 | D40: =_xlfn.XLOOKUP(C40,Folha2!A:A,Folha2!B:B) -> TAKE AWAY | E40: =MID(A40,5,3) -> 053 | F40: =MID(B40,5,2) -> 34 | G40: =MID(B40,8,2) -> 13 | H40: 01826736 | I40: BACALHAU COM NATAS 250G | J40: PORSI | K40: 5604260304073 | L40: MP | M40: N | N40: N | O40: N | P40: N | Q40: 01 | R40: 3.29 | S40: 3.32 | Y40: =IF(OR(N40="O",O40="O"),IF(COUNT(V40:X40)>0,MIN(V40:X40),MIN(S40:U40)),IF(M40="O",MIN(S40:U40),IF(L40="E",IFERROR(MODE(S40:U40),MIN(S40:U40)),AVERAGE(S40:U40)))) -> 3.32 | Z40: =R40/Y40-1 -> -0.0090361446 | AA40: =R40-Y40 -> -0.03 | AB40: =R40=Y40 -> FALSE
A41: g27b053 | B41: r40f34s13 | C41: =MID(A41,2,2) -> 27 | D41: =_xlfn.XLOOKUP(C41,Folha2!A:A,Folha2!B:B) -> TAKE AWAY | E41: =MID(A41,5,3) -> 053 | F41: =MID(B41,5,2) -> 34 | G41: =MID(B41,8,2) -> 13 | H41: 01856010 | I41: BACALHAU A BRAS 250G | J41: PORSI | K41: 5604260309894 | L41: MP | M41: N | N41: N | O41: N | P41: N | Q41: 01 | R41: 3.99 | S41: 3.99 | Y41: =IF(OR(N41="O",O41="O"),IF(COUNT(V41:X41)>0,MIN(V41:X41),MIN(S41:U41)),IF(M41="O",MIN(S41:U41),IF(L41="E",IFERROR(MODE(S41:U41),MIN(S41:U41)),AVERAGE(S41:U41)))) -> 3.99 | Z41: =R41/Y41-1 -> 0 | AA41: =R41-Y41 -> 0 | AB41: =R41=Y41 -> TRUE | AC41: 09-07-2026 | AD41: 3.99
...

Sheet Folha2
A1: Grp | B1: GRUPO
A2: 27 | B2: TAKE AWAY
A3: 37 | B3: BVP
A4: 38 | B4: CARNES E AVES
A5: 41 | B5: MAR
A6: 42 | B6: FRUTAS E LEGUMES
A7: 43 | B7: FRESCOS LACTEOS
A8: 44 | B8: FRESCOS NAO LACTEOS
A9: 45 | B9: DPH
A10: 46 | B10: MERCEARIA DOCE
A11: 47 | B11: MERCEARIA SALGADA
A12: 48 | B12: BEBIDAS
... A15: 51 | B15: TEXTIL
